[2024-02-26 00:12:14,943] {/Users/raghavmaini/Desktop/rttMVP/rttDataService/env/lib/python3.11/site-packages/flask/app.py:828} ERROR - Exception on /login [POST]
Traceback (most recent call last):
  File "/Users/raghavmaini/Desktop/rttMVP/rttDataService/env/lib/python3.11/site-packages/flask/app.py", line 1463, in wsgi_app
    response = self.full_dispatch_request()
               ^^^^^^^^^^^^^^^^^^^^^^^^^^^^
  File "/Users/raghavmaini/Desktop/rttMVP/rttDataService/env/lib/python3.11/site-packages/flask/app.py", line 872, in full_dispatch_request
    rv = self.handle_user_exception(e)
         ^^^^^^^^^^^^^^^^^^^^^^^^^^^^^
  File "/Users/raghavmaini/Desktop/rttMVP/rttDataService/env/lib/python3.11/site-packages/flask_cors/extension.py", line 176, in wrapped_function
    return cors_after_request(app.make_response(f(*args, **kwargs)))
                                                ^^^^^^^^^^^^^^^^^^
  File "/Users/raghavmaini/Desktop/rttMVP/rttDataService/env/lib/python3.11/site-packages/flask/app.py", line 870, in full_dispatch_request
    rv = self.dispatch_request()
         ^^^^^^^^^^^^^^^^^^^^^^^
  File "/Users/raghavmaini/Desktop/rttMVP/rttDataService/env/lib/python3.11/site-packages/flask/app.py", line 855, in dispatch_request
    return self.ensure_sync(self.view_functions[rule.endpoint])(**view_args)  # type: ignore[no-any-return]
           ^^^^^^^^^^^^^^^^^^^^^^^^^^^^^^^^^^^^^^^^^^^^^^^^^^^^^^^^^^^^^^^^^
  File "/Users/raghavmaini/Desktop/rttMVP/rttDataService/routes/login.py", line 28, in login
    return User().authenticate_returning_user(username, password)
           ^^^^^^^^^^^^^^^^^^^^^^^^^^^^^^^^^^^^^^^^^^^^^^^^^^^^^^
  File "/Users/raghavmaini/Desktop/rttMVP/rttDataService/models/user.py", line 377, in authenticate_returning_user
    user_details = self.__get_user_details(user_id, True)
                   ^^^^^^^^^^^^^^^^^^^^^^^^^^^^^^^^^^^^^^
  File "/Users/raghavmaini/Desktop/rttMVP/rttDataService/models/user.py", line 177, in __get_user_details
    'accountCreationTime': self.__fetch_account_creation_time(user_id),
                           ^^^^^^^^^^^^^^^^^^^^^^^^^^^^^^^^^^^^^^^^^^^
  File "/Users/raghavmaini/Desktop/rttMVP/rttDataService/models/user.py", line 34, in __fetch_account_creation_time
    creation_time = self.cursor.fetchone().get('creation_time').isoformat()
                    ^^^^^^^^^^^^^^^^^^^^^^^^^^^^^^^^^^^^^^^^^^^^^^^^^^^^^
AttributeError: 'str' object has no attribute 'isoformat'
[2024-02-26 00:12:30,448] {/Users/raghavmaini/Desktop/rttMVP/rttDataService/env/lib/python3.11/site-packages/flask/app.py:828} ERROR - Exception on /login [POST]
Traceback (most recent call last):
  File "/Users/raghavmaini/Desktop/rttMVP/rttDataService/env/lib/python3.11/site-packages/flask/app.py", line 1463, in wsgi_app
    response = self.full_dispatch_request()
               ^^^^^^^^^^^^^^^^^^^^^^^^^^^^
  File "/Users/raghavmaini/Desktop/rttMVP/rttDataService/env/lib/python3.11/site-packages/flask/app.py", line 872, in full_dispatch_request
    rv = self.handle_user_exception(e)
         ^^^^^^^^^^^^^^^^^^^^^^^^^^^^^
  File "/Users/raghavmaini/Desktop/rttMVP/rttDataService/env/lib/python3.11/site-packages/flask_cors/extension.py", line 176, in wrapped_function
    return cors_after_request(app.make_response(f(*args, **kwargs)))
                                                ^^^^^^^^^^^^^^^^^^
  File "/Users/raghavmaini/Desktop/rttMVP/rttDataService/env/lib/python3.11/site-packages/flask/app.py", line 870, in full_dispatch_request
    rv = self.dispatch_request()
         ^^^^^^^^^^^^^^^^^^^^^^^
  File "/Users/raghavmaini/Desktop/rttMVP/rttDataService/env/lib/python3.11/site-packages/flask/app.py", line 855, in dispatch_request
    return self.ensure_sync(self.view_functions[rule.endpoint])(**view_args)  # type: ignore[no-any-return]
           ^^^^^^^^^^^^^^^^^^^^^^^^^^^^^^^^^^^^^^^^^^^^^^^^^^^^^^^^^^^^^^^^^
  File "/Users/raghavmaini/Desktop/rttMVP/rttDataService/routes/login.py", line 28, in login
    return User().authenticate_returning_user(username, password)
           ^^^^^^^^^^^^^^^^^^^^^^^^^^^^^^^^^^^^^^^^^^^^^^^^^^^^^^
  File "/Users/raghavmaini/Desktop/rttMVP/rttDataService/models/user.py", line 377, in authenticate_returning_user
    user_details = self.__get_user_details(user_id, True)
                   ^^^^^^^^^^^^^^^^^^^^^^^^^^^^^^^^^^^^^^
  File "/Users/raghavmaini/Desktop/rttMVP/rttDataService/models/user.py", line 177, in __get_user_details
    'accountCreationTime': self.__fetch_account_creation_time(user_id),
                           ^^^^^^^^^^^^^^^^^^^^^^^^^^^^^^^^^^^^^^^^^^^
  File "/Users/raghavmaini/Desktop/rttMVP/rttDataService/models/user.py", line 34, in __fetch_account_creation_time
    creation_time:datetime = self.cursor.fetchone().get('creation_time').isoformat()
                             ^^^^^^^^^^^^^^^^^^^^^^^^^^^^^^^^^^^^^^^^^^^^^^^^^^^^^
AttributeError: 'str' object has no attribute 'isoformat'
[2024-02-26 13:30:38,638] {/Users/raghavmaini/Desktop/rttMVP/rttDataService/env/lib/python3.11/site-packages/flask/app.py:828} ERROR - Exception on /signup [PUT]
Traceback (most recent call last):
  File "/Users/raghavmaini/Desktop/rttMVP/rttDataService/env/lib/python3.11/site-packages/flask/app.py", line 1463, in wsgi_app
    response = self.full_dispatch_request()
               ^^^^^^^^^^^^^^^^^^^^^^^^^^^^
  File "/Users/raghavmaini/Desktop/rttMVP/rttDataService/env/lib/python3.11/site-packages/flask/app.py", line 872, in full_dispatch_request
    rv = self.handle_user_exception(e)
         ^^^^^^^^^^^^^^^^^^^^^^^^^^^^^
  File "/Users/raghavmaini/Desktop/rttMVP/rttDataService/env/lib/python3.11/site-packages/flask_cors/extension.py", line 176, in wrapped_function
    return cors_after_request(app.make_response(f(*args, **kwargs)))
                                                ^^^^^^^^^^^^^^^^^^
  File "/Users/raghavmaini/Desktop/rttMVP/rttDataService/env/lib/python3.11/site-packages/flask/app.py", line 870, in full_dispatch_request
    rv = self.dispatch_request()
         ^^^^^^^^^^^^^^^^^^^^^^^
  File "/Users/raghavmaini/Desktop/rttMVP/rttDataService/env/lib/python3.11/site-packages/flask/app.py", line 855, in dispatch_request
    return self.ensure_sync(self.view_functions[rule.endpoint])(**view_args)  # type: ignore[no-any-return]
           ^^^^^^^^^^^^^^^^^^^^^^^^^^^^^^^^^^^^^^^^^^^^^^^^^^^^^^^^^^^^^^^^^
  File "/Users/raghavmaini/Desktop/rttMVP/rttDataService/routes/login.py", line 16, in signup
    return User().signup(data)
           ^^^^^^
  File "/Users/raghavmaini/Desktop/rttMVP/rttDataService/models/user.py", line 18, in __init__
    self.conn = self.db_manager.get_db_connection()
                ^^^^^^^^^^^^^^^^^^^^^^^^^^^^^^^^^^^
  File "/Users/raghavmaini/Desktop/rttMVP/rttDataService/utils/db_manager.py", line 9, in get_db_connection
    if 'sqlite' in current_app.config['DATABASE_URI']:
                   ~~~~~~~~~~~~~~~~~~^^^^^^^^^^^^^^^^
KeyError: 'DATABASE_URI'
[2024-02-26 13:31:49,932] {/Users/raghavmaini/Desktop/rttMVP/rttDataService/env/lib/python3.11/site-packages/flask/app.py:828} ERROR - Exception on /signup [PUT]
Traceback (most recent call last):
  File "/Users/raghavmaini/Desktop/rttMVP/rttDataService/env/lib/python3.11/site-packages/flask/app.py", line 1463, in wsgi_app
    response = self.full_dispatch_request()
               ^^^^^^^^^^^^^^^^^^^^^^^^^^^^
  File "/Users/raghavmaini/Desktop/rttMVP/rttDataService/env/lib/python3.11/site-packages/flask/app.py", line 872, in full_dispatch_request
    rv = self.handle_user_exception(e)
         ^^^^^^^^^^^^^^^^^^^^^^^^^^^^^
  File "/Users/raghavmaini/Desktop/rttMVP/rttDataService/env/lib/python3.11/site-packages/flask_cors/extension.py", line 176, in wrapped_function
    return cors_after_request(app.make_response(f(*args, **kwargs)))
                                                ^^^^^^^^^^^^^^^^^^
  File "/Users/raghavmaini/Desktop/rttMVP/rttDataService/env/lib/python3.11/site-packages/flask/app.py", line 870, in full_dispatch_request
    rv = self.dispatch_request()
         ^^^^^^^^^^^^^^^^^^^^^^^
  File "/Users/raghavmaini/Desktop/rttMVP/rttDataService/env/lib/python3.11/site-packages/flask/app.py", line 855, in dispatch_request
    return self.ensure_sync(self.view_functions[rule.endpoint])(**view_args)  # type: ignore[no-any-return]
           ^^^^^^^^^^^^^^^^^^^^^^^^^^^^^^^^^^^^^^^^^^^^^^^^^^^^^^^^^^^^^^^^^
  File "/Users/raghavmaini/Desktop/rttMVP/rttDataService/routes/login.py", line 16, in signup
    return User().signup(data)
           ^^^^^^
  File "/Users/raghavmaini/Desktop/rttMVP/rttDataService/models/user.py", line 19, in __init__
    self.cursor = self.conn.cursor(cursor=pymysql.cursors.DictCursor)
                  ^^^^^^^^^^^^^^^^^^^^^^^^^^^^^^^^^^^^^^^^^^^^^^^^^^^
TypeError: 'cursor' is an invalid keyword argument for cursor()
