[2024-02-26 15:20:36,935] {/Users/raghavmaini/Desktop/rttMVP/rttDataService/env/lib/python3.11/site-packages/flask/app.py:828} ERROR - Exception on /signup [PUT]
Traceback (most recent call last):
  File "/Users/raghavmaini/Desktop/rttMVP/rttDataService/utils/user.py", line 469, in signup
    user_id = self.__create_user_and_fetch_id(full_name, username,
             ^^^^^^^^^^^^^^^^^^^^^^^^^^^^^^^^^^^^^^^^^^^^^^^^^^^^
  File "/Users/raghavmaini/Desktop/rttMVP/rttDataService/utils/user.py", line 257, in __create_user_and_fetch_id
    self.cursor.execute("""
    ^^^^^^^^^^^
AttributeError: 'User' object has no attribute 'cursor'

During handling of the above exception, another exception occurred:

Traceback (most recent call last):
  File "/Users/raghavmaini/Desktop/rttMVP/rttDataService/env/lib/python3.11/site-packages/flask/app.py", line 1463, in wsgi_app
    response = self.full_dispatch_request()
               ^^^^^^^^^^^^^^^^^^^^^^^^^^^^
  File "/Users/raghavmaini/Desktop/rttMVP/rttDataService/env/lib/python3.11/site-packages/flask/app.py", line 872, in full_dispatch_request
    rv = self.handle_user_exception(e)
         ^^^^^^^^^^^^^^^^^^^^^^^^^^^^^
  File "/Users/raghavmaini/Desktop/rttMVP/rttDataService/env/lib/python3.11/site-packages/flask_cors/extension.py", line 176, in wrapped_function
    return cors_after_request(app.make_response(f(*args, **kwargs)))
                                                ^^^^^^^^^^^^^^^^^^
  File "/Users/raghavmaini/Desktop/rttMVP/rttDataService/env/lib/python3.11/site-packages/flask/app.py", line 870, in full_dispatch_request
    rv = self.dispatch_request()
         ^^^^^^^^^^^^^^^^^^^^^^^
  File "/Users/raghavmaini/Desktop/rttMVP/rttDataService/env/lib/python3.11/site-packages/flask/app.py", line 855, in dispatch_request
    return self.ensure_sync(self.view_functions[rule.endpoint])(**view_args)  # type: ignore[no-any-return]
           ^^^^^^^^^^^^^^^^^^^^^^^^^^^^^^^^^^^^^^^^^^^^^^^^^^^^^^^^^^^^^^^^^
  File "/Users/raghavmaini/Desktop/rttMVP/rttDataService/routes/login.py", line 16, in signup
    return User().signup(data)
           ^^^^^^^^^^^^^^^^^^^
  File "/Users/raghavmaini/Desktop/rttMVP/rttDataService/utils/user.py", line 491, in signup
    self.conn.commit()
    ^^^^^^^^^
AttributeError: 'User' object has no attribute 'conn'
